<?xml version="1.0" encoding="utf-8"?>
<!-- =================================================================================== -->
<!-- |    This document was autogenerated by xacro from plotterv2.xacro                | -->
<!-- |    EDITING THIS FILE BY HAND IS NOT RECOMMENDED                                 | -->
<!-- =================================================================================== -->
<robot name="plotter">
  <!-- END - Include -->
  <link name="link_00">
    <inertial>
      <mass value="1024"/>
      <origin rpy="0 0 0" xyz="0 0 0"/>
      <inertia ixx="170.667" ixy="0" ixz="0" iyy="170.67" iyz="0" izz="170.67"/>
    </inertial>
    <collision>
      <origin rpy="0 0 0" xyz="0 0 0"/>
      <geometry>
        <box size="0.032 0.004 0.068"/>
      </geometry>
    </collision>
    <visual>
      <origin rpy="0 0 0" xyz="0 0 0"/>
      <geometry>
        <box size="0.032 0.004 0.068"/>
      </geometry>
    </visual>
  </link>
  <joint name="link_00__link_01" type="fixed">
    <origin rpy="0 0 0" xyz="0 0.002 0"/>
    <parent link="link_00"/>
    <child link="link_01"/>
  </joint>
  <transmission name="trans_link_00__link_01">
    <type>transmission_interface/SimpleTransmission</type>
    <joint name="link_00__link_01">
      <hardwareInterface>hardware_interface/EffortJointInterface</hardwareInterface>
    </joint>
    <actuator name="motor_link_00__link_01">
      <hardwareInterface>hardware_interface/EffortJointInterface</hardwareInterface>
      <mechanicalReduction>1</mechanicalReduction>
    </actuator>
  </transmission>
  <link name="link_01">
    <inertial>
      <mass value="1024"/>
      <origin rpy="0 0 0" xyz="0 0.018 0"/>
      <inertia ixx="170.667" ixy="0" ixz="0" iyy="170.67" iyz="0" izz="170.67"/>
    </inertial>
    <collision>
      <origin rpy="0 0 0" xyz="0 0.018 0"/>
      <geometry>
        <box size="0.02 0.036 0.045"/>
      </geometry>
    </collision>
    <visual>
      <origin rpy="0 0 0" xyz="0 0.018 0"/>
      <geometry>
        <box size="0.02 0.036 0.045"/>
      </geometry>
    </visual>
  </link>
  <joint name="link_01__link_02" type="revolute">
    <axis xyz="0 0 1"/>
    <limit effort="1000.0" lower="-1.57" upper="1.57" velocity="0.5"/>
    <origin rpy="0 0 0" xyz="0 0.036 0"/>
    <parent link="link_01"/>
    <child link="link_02"/>
  </joint>
  <transmission name="trans_link_01__link_02">
    <type>transmission_interface/SimpleTransmission</type>
    <joint name="link_01__link_02">
      <hardwareInterface>hardware_interface/EffortJointInterface</hardwareInterface>
    </joint>
    <actuator name="motor_link_01__link_02">
      <hardwareInterface>hardware_interface/EffortJointInterface</hardwareInterface>
      <mechanicalReduction>1</mechanicalReduction>
    </actuator>
  </transmission>
  <link name="link_02">
    <inertial>
      <mass value="1024"/>
      <origin rpy="0 0 0" xyz="0 0.0305 0"/>
      <inertia ixx="170.667" ixy="0" ixz="0" iyy="170.67" iyz="0" izz="170.67"/>
    </inertial>
    <collision>
      <origin rpy="0 0 0" xyz="0 0.0305 0"/>
      <geometry>
        <box size="0.02 0.061 0.057"/>
      </geometry>
    </collision>
    <visual>
      <origin rpy="0 0 0" xyz="0 0.0305 0"/>
      <geometry>
        <box size="0.02 0.061 0.057"/>
      </geometry>
    </visual>
  </link>
  <joint name="link_02__link_03" type="revolute">
    <axis xyz="0 0 1"/>
    <limit effort="1000.0" lower="-1.57" upper="1.57" velocity="0.5"/>
    <origin rpy="0 0 0" xyz="0 0.061 0"/>
    <parent link="link_02"/>
    <child link="link_03"/>
  </joint>
  <transmission name="trans_link_02__link_03">
    <type>transmission_interface/SimpleTransmission</type>
    <joint name="link_02__link_03">
      <hardwareInterface>hardware_interface/EffortJointInterface</hardwareInterface>
    </joint>
    <actuator name="motor_link_02__link_03">
      <hardwareInterface>hardware_interface/EffortJointInterface</hardwareInterface>
      <mechanicalReduction>1</mechanicalReduction>
    </actuator>
  </transmission>
  <link name="link_03">
    <inertial>
      <mass value="1024"/>
      <origin rpy="0 0 0" xyz="0 0.013 0"/>
      <inertia ixx="170.667" ixy="0" ixz="0" iyy="170.67" iyz="0" izz="170.67"/>
    </inertial>
    <collision>
      <origin rpy="0 0 0" xyz="0 0.013 0"/>
      <geometry>
        <box size="0.02 0.026 0.057"/>
      </geometry>
    </collision>
    <visual>
      <origin rpy="0 0 0" xyz="0 0.013 0"/>
      <geometry>
        <box size="0.02 0.026 0.057"/>
      </geometry>
    </visual>
  </link>
  <gazebo>
    <plugin filename="libgazebo_ros_control.so" name="gazebo_ros_control">
      <robotNamespace>/plotter</robotNamespace>
      <robotSimType>gazebo_ros_control/DefaultRobotHWSim</robotSimType>
    </plugin>
  </gazebo>
</robot>
