<?xml version="1.0" encoding="utf-8"?>
<!-- =================================================================================== -->
<!-- |    This document was autogenerated by xacro from plotterv2.xacro                | -->
<!-- |    EDITING THIS FILE BY HAND IS NOT RECOMMENDED                                 | -->
<!-- =================================================================================== -->
<robot name="plotter">
  <!-- END - Include -->
  <!-- BGN - Robot description -->
  <link name="world"/>
  <joint name="world__link_01" type="fixed">
    <parent link="world"/>
    <child link="link_01"/>
  </joint>
  <!--
    <link name="${link_00_name}" />

    <joint name="${link_00_name}__${link_01_name}" type="fixed">
        <parent link="${link_00_name}"/>
        <child link="${link_01_name}"/>
    </joint>

    
    <xacro:m_link_box name="${link_00_name}" origin_rpy="0 0 0" origin_xyz = "0 0 0"
              mass = "1024"
              ixx = "170.667" ixy = "0" ixz = "0"
              iyy = "170.67"  iyz = "0"
              izz = "170.67"
              size = "0.032 0.004 0.068" />

   

    <xacro:m_joint name="${link_00_name}__${link_01_name}" type="fixed"
	axis_xyz = "0 0 1"
	origin_rpy ="0 0 0" origin_xyz = "0 ${0.004/2} 0"
        parent = "${link_00_name}"  child = "${link_01_name}"
        limit_e = "1000.0" 
        limit_l = "-1.57"  
        limit_u = "1.57"   
        limit_v = "0.5" />


    <xacro:m_joint_fixed name="${link_00_name}__${link_01_name}" type="fixed"
       origin_rpy ="0 0 0" origin_xyz = "0 ${0.004/2} 0"
       parent = "${link_00_name}"  child = "${link_01_name}" />
-->
  <link name="link_01">
    <inertial>
      <mass value="0.01"/>
      <origin rpy="0 0 0" xyz="0 0.018 0.2"/>
      <inertia ixx="0.4" ixy="0" ixz="0" iyy="0.4" iyz="0" izz="0.4"/>
    </inertial>
    <collision>
      <origin rpy="0 0 0" xyz="0 0.018 0.2"/>
      <geometry>
        <box size="0.02 0.036 0.045"/>
      </geometry>
    </collision>
    <visual>
      <origin rpy="0 0 0" xyz="0 0.018 0.2"/>
      <geometry>
        <box size="0.02 0.036 0.045"/>
      </geometry>
    </visual>
  </link>
  <joint name="link_01__link_02" type="revolute">
    <axis xyz="0 0 1"/>
    <limit effort="3.0" lower="-1.57" upper="1.57" velocity="0.5"/>
    <origin rpy="0 0 0" xyz="0 0.036 0.2"/>
    <parent link="link_01"/>
    <child link="link_02"/>
  </joint>
  <transmission name="trans_link_01__link_02">
    <type>transmission_interface/SimpleTransmission</type>
    <joint name="link_01__link_02">
      <hardwareInterface>hardware_interface/PositionJointInterface</hardwareInterface>
    </joint>
    <actuator name="motor_link_01__link_02">
      <hardwareInterface>hardware_interface/PositionJointInterface</hardwareInterface>
      <mechanicalReduction>1</mechanicalReduction>
    </actuator>
  </transmission>
  <link name="link_02">
    <inertial>
      <mass value="0.01"/>
      <origin rpy="0 0 0" xyz="0 0.0305 0"/>
      <inertia ixx="0.4" ixy="0" ixz="0" iyy="0.4" iyz="0" izz="0.4"/>
    </inertial>
    <collision>
      <origin rpy="0 0 0" xyz="0 0.0305 0"/>
      <geometry>
        <box size="0.02 0.061 0.057"/>
      </geometry>
    </collision>
    <visual>
      <origin rpy="0 0 0" xyz="0 0.0305 0"/>
      <geometry>
        <box size="0.02 0.061 0.057"/>
      </geometry>
    </visual>
  </link>
  <joint name="link_02__link_03" type="revolute">
    <axis xyz="0 0 1"/>
    <limit effort="3.0" lower="-1.57" upper="1.57" velocity="0.5"/>
    <origin rpy="0 0 0" xyz="0 0.061 0"/>
    <parent link="link_02"/>
    <child link="link_03"/>
  </joint>
  <transmission name="trans_link_02__link_03">
    <type>transmission_interface/SimpleTransmission</type>
    <joint name="link_02__link_03">
      <hardwareInterface>hardware_interface/PositionJointInterface</hardwareInterface>
    </joint>
    <actuator name="motor_link_02__link_03">
      <hardwareInterface>hardware_interface/PositionJointInterface</hardwareInterface>
      <mechanicalReduction>1</mechanicalReduction>
    </actuator>
  </transmission>
  <link name="link_03">
    <inertial>
      <mass value="0.01"/>
      <origin rpy="0 0 0" xyz="0 0.013 0"/>
      <inertia ixx="0.4" ixy="0" ixz="0" iyy="0.4" iyz="0" izz="0.4"/>
    </inertial>
    <collision>
      <origin rpy="0 0 0" xyz="0 0.013 0"/>
      <geometry>
        <box size="0.02 0.026 0.057"/>
      </geometry>
    </collision>
    <visual>
      <origin rpy="0 0 0" xyz="0 0.013 0"/>
      <geometry>
        <box size="0.02 0.026 0.057"/>
      </geometry>
    </visual>
  </link>
  <gazebo>
    <plugin filename="libgazebo_ros_control.so" name="gazebo_ros_control">
      <robotNamespace>/plotter</robotNamespace>
      <robotSimType>gazebo_ros_control/DefaultRobotHWSim</robotSimType>
    </plugin>
  </gazebo>
</robot>
