<?xml version="1.0" encoding="utf-8"?>
<!-- =================================================================================== -->
<!-- |    This document was autogenerated by xacro from robot_4wd.xacro                | -->
<!-- |    EDITING THIS FILE BY HAND IS NOT RECOMMENDED                                 | -->
<!-- =================================================================================== -->
<robot name="robot_4wd">
  <!--
  Comandos: executed in jetson-ros
  cd catkin_ws
  source devel/setup.bash
  roslaunch robot_4wd_description robot_4wd.launch

  para ver si esta todo ok. esto es porque el comando roslaunch no da un mensaje claro si se cae el xacro

  cd ~/catkin_ws/src/robot_4wd_description/urdf
  rosrun xacro xacro - -inorder -o robot_4wd.urdf robot_4wd.xacro    las rallitas vas pegadas
  
-->
  <!--
  To avoid: 
  The root link base_footprint has an inertia specified in the URDF, but KDL does not support a root link with an inertia.  As a workaround, you can add an extra dummy link to your URDF.

-->
  <link name="dummy">
</link>
  <link name="base_footprint">
    <inertial>
      <mass value="20"/>
      <inertia ixx="3.33333333333e-06" ixy="0.0" ixz="0.0" iyy="3.33333333333e-06" iyz="0.0" izz="3.33333333333e-06"/>
    </inertial>
    <visual>
      <origin rpy="0 0 0" xyz="0 0 0"/>
      <geometry>
        <box size="0.001 0.001 0.001"/>
      </geometry>
    </visual>
  </link>
  <joint name="dummy_joint" type="fixed">
    <parent link="dummy"/>
    <child link="base_footprint"/>
  </joint>
  <link name="case">
    <inertial>
      <mass value="20"/>
      <inertia ixx="3.33333333333e-06" ixy="0.0" ixz="0.0" iyy="3.33333333333e-06" iyz="0.0" izz="3.33333333333e-06"/>
    </inertial>
    <visual>
      <origin rpy="0 0 0" xyz="0 0 0"/>
      <geometry>
        <box size="0.22 0.159 0.322"/>
      </geometry>
    </visual>
  </link>
  <joint name="base_link_joint" type="fixed">
    <origin rpy="0 0 0" xyz="0 0 0.2155"/>
    <parent link="base_footprint"/>
    <child link="case"/>
  </joint>
  <link name="front_left_wheel">
    <visual>
      <origin rpy="1.57079632679 0 0" xyz="0 0 0"/>
      <geometry>
        <cylinder length="0.027" radius="0.0325"/>
      </geometry>
    </visual>
    <collision>
      <origin rpy="1.57079632679 0 0" xyz="0 0 0"/>
      <geometry>
        <cylinder length="0.027" radius="0.0325"/>
      </geometry>
    </collision>
    <inertial>
      <mass value="10"/>
      <inertia ixx="0.00308333333333" ixy="0" ixz="0" iyy="0.00308333333333" iyz="0" izz="0.006125"/>
    </inertial>
  </link>
  <joint name="front_left_wheel_joint" type="continuous">
    <axis rpy="0 0 0" xyz="0 1 0"/>
    <parent link="case"/>
    <child link="front_left_wheel"/>
    <origin rpy="0 0 0" xyz="0.04571 -0.094 -0.183"/>
  </joint>
  <link name="front_right_wheel">
    <visual>
      <origin rpy="1.57079632679 0 0" xyz="0 0 0"/>
      <geometry>
        <cylinder length="0.027" radius="0.0325"/>
      </geometry>
    </visual>
    <collision>
      <origin rpy="1.57079632679 0 0" xyz="0 0 0"/>
      <geometry>
        <cylinder length="0.027" radius="0.0325"/>
      </geometry>
    </collision>
    <inertial>
      <mass value="10"/>
      <inertia ixx="0.00308333333333" ixy="0" ixz="0" iyy="0.00308333333333" iyz="0" izz="0.006125"/>
    </inertial>
  </link>
  <joint name="front_right_wheel_joint" type="continuous">
    <axis rpy="0 0 0" xyz="0 1 0"/>
    <parent link="case"/>
    <child link="front_right_wheel"/>
    <origin rpy="0 0 0" xyz="0.04571 0.094 -0.183"/>
  </joint>
  <link name="back_left_wheel">
    <visual>
      <origin rpy="1.57079632679 0 0" xyz="0 0 0"/>
      <geometry>
        <cylinder length="0.027" radius="0.0325"/>
      </geometry>
    </visual>
    <collision>
      <origin rpy="1.57079632679 0 0" xyz="0 0 0"/>
      <geometry>
        <cylinder length="0.027" radius="0.0325"/>
      </geometry>
    </collision>
    <inertial>
      <mass value="10"/>
      <inertia ixx="0.00308333333333" ixy="0" ixz="0" iyy="0.00308333333333" iyz="0" izz="0.006125"/>
    </inertial>
  </link>
  <joint name="back_left_wheel_joint" type="continuous">
    <axis rpy="0 0 0" xyz="0 1 0"/>
    <parent link="case"/>
    <child link="back_left_wheel"/>
    <origin rpy="0 0 0" xyz="-0.04571 -0.094 -0.183"/>
  </joint>
  <link name="back_right_wheel">
    <visual>
      <origin rpy="1.57079632679 0 0" xyz="0 0 0"/>
      <geometry>
        <cylinder length="0.027" radius="0.0325"/>
      </geometry>
    </visual>
    <collision>
      <origin rpy="1.57079632679 0 0" xyz="0 0 0"/>
      <geometry>
        <cylinder length="0.027" radius="0.0325"/>
      </geometry>
    </collision>
    <inertial>
      <mass value="10"/>
      <inertia ixx="0.00308333333333" ixy="0" ixz="0" iyy="0.00308333333333" iyz="0" izz="0.006125"/>
    </inertial>
  </link>
  <joint name="back_right_wheel_joint" type="continuous">
    <axis rpy="0 0 0" xyz="0 1 0"/>
    <parent link="case"/>
    <child link="back_right_wheel"/>
    <origin rpy="0 0 0" xyz="-0.04571 0.094 -0.183"/>
  </joint>
  <link name="base_sensor_laser">
    <inertial>
      <mass value="20"/>
      <inertia ixx="3.33333333333e-06" ixy="0.0" ixz="0.0" iyy="3.33333333333e-06" iyz="0.0" izz="3.33333333333e-06"/>
    </inertial>
    <visual>
      <origin rpy="0 0 0" xyz="0 0 0"/>
      <geometry>
        <box size="0.071 0.071 0.106"/>
      </geometry>
    </visual>
  </link>
  <joint name="joint_base_sensor_laser" type="fixed">
    <origin rpy="0 0 0" xyz="0 0 0.214"/>
    <parent link="case"/>
    <child link="base_sensor_laser"/>
  </joint>
  <link name="sensor_laser">
    <visual>
      <origin rpy="0 0 0" xyz="0 0 0"/>
      <geometry>
        <cylinder length="0.024" radius="0.0355"/>
      </geometry>
      <material name="white"/>
    </visual>
    <collision>
      <origin rpy="0 0 0" xyz="0 0 0"/>
      <geometry>
        <cylinder length="0.024" radius="0.0355"/>
      </geometry>
    </collision>
    <inertial>
      <mass value="1"/>
      <inertia ixx="0.0003630625" ixy="0" ixz="0" iyy="0.0003630625" iyz="0" izz="0.000630125"/>
    </inertial>
  </link>
  <joint name="joint_sensor_laser" type="fixed">
    <origin rpy="0 0 0" xyz="0.15 0 0.05"/>
    <parent link="base_sensor_laser"/>
    <child link="sensor_laser"/>
  </joint>
</robot>
